Workbook

Sheet Vendor Inventory
A1: Vendor ID | B1: Vendor Name | C1: Vendor Category | D1: Business Capability | E1: Supporting Application | F1: Business Owner | G1: Technology Owner | H1: Executive Sponsor | I1: Vendor Tier | J1: Data Classification | K1: Geographic Region | L1: Regulatory Impact | M1: Assessment Date | N1: Assessment Expiry | O1: Governance Score | P1: Security Score | Q1: Business Dependency Score | R1: Continuous Monitoring Score | S1: Concentration & Resilience Score | T1: Composite Score | U1: Risk Tier | V1: Continuous Monitoring | W1: Contract Renewal | X1: Assessment Half-Life (Days) | Y1: Current Status | Z1: Notes
A2: V001 | B2: Microsoft | C2: Cloud & Productivity | D2: Enterprise IT | E2: Microsoft 365 / Entra ID / Sentinel | F2: Director, Enterprise IT Services | G2: Enterprise Infrastructure Manager | H2: CIO | I2: Critical | J2: Restricted | K2: Global | L2: GDPR; ISO 27001 | M2: 46204 | N2: =M2+X2 -> 46294 | O2: 95 | P2: 96 | Q2: 98 | R2: 95 | S2: 65 | T2: =ROUND((O2*25%)+(P2*25%)+(Q2*20%)+(R2*20%)+(S2*10%),0) -> 93 | U2: {=_xlfn.IFS(T2>=90,"Low",T2>=75,"Moderate",T2>=60,"Elevated",TRUE,"High")} -> Low | V2: =IF(OR(I2="Critical",I2="High"),"Yes","No") -> Yes | W2: 46752 | X2: =_xlfn.XLOOKUP(I2,'Lookup Tables'!$H$4:$H$7,'Lookup Tables'!$I$4:$I$7) -> 90 | Y2: Approved | Z2: Strategic enterprise cloud and productivity provider. Continuous monitoring enabled.
A3: V002 | B3: SAP | C3: ERP | D3: Finance & Procurement | E3: SAP S/4HANA | F3: VP, Finance & Procurement | G3: ERP Platform Manager | H3: CFO | I3: Critical | J3: Restricted | K3: Global | L3: GDPR; SOX | M3: 46204 | N3: =M3+X3 -> 46294 | O3: 94 | P3: 92 | Q3: 97 | R3: 90 | S3: 70 | T3: =ROUND((O3*25%)+(P3*25%)+(Q3*20%)+(R3*20%)+(S3*10%),0) -> 91 | U3: {=_xlfn.IFS(T3>=90,"Low",T3>=75,"Moderate",T3>=60,"Elevated",TRUE,"High")} -> Low | V3: =IF(OR(I3="Critical",I3="High"),"Yes","No") -> Yes | W3: 46752 | X3: =_xlfn.XLOOKUP(I3,'Lookup Tables'!$H$4:$H$7,'Lookup Tables'!$I$4:$I$7) -> 90 | Y3: Approved | Z3: Enterprise ERP platform supporting finance and procurement.
A4: V003 | B4: Snowflake | C4: Data Platform | D4: Enterprise Analytics | E4: InsightOps | F4: Director, Enterprise Analytics | G4: Data Platform Manager | H4: Chief Data & AI Officer | I4: Critical | J4: Restricted | K4: Global | L4: GDPR | M4: 46204 | N4: =M4+X4 -> 46294 | O4: 90 | P4: 92 | Q4: 88 | R4: 91 | S4: 72 | T4: =ROUND((O4*25%)+(P4*25%)+(Q4*20%)+(R4*20%)+(S4*10%),0) -> 89 | U4: {=_xlfn.IFS(T4>=90,"Low",T4>=75,"Moderate",T4>=60,"Elevated",TRUE,"High")} -> Moderate | V4: =IF(OR(I4="Critical",I4="High"),"Yes","No") -> Yes | W4: 46752 | X4: =_xlfn.XLOOKUP(I4,'Lookup Tables'!$H$4:$H$7,'Lookup Tables'!$I$4:$I$7) -> 90 | Y4: Approved | Z4: Strategic analytics platform hosting enterprise reporting workloads.
A5: V004 | B5: NaviEdge Solutions | C5: AI Edge Computing | D5: Port Operations | E5: PortFlow | F5: VP, Port Operations | G5: Logistics Systems Manager | H5: COO | I5: Critical | J5: Restricted | K5: Global | L5: GDPR; EU AI Act | M5: 46204 | N5: =M5+X5 -> 46294 | O5: 82 | P5: 84 | Q5: 96 | R5: 80 | S5: 60 | T5: =ROUND((O5*25%)+(P5*25%)+(Q5*20%)+(R5*20%)+(S5*10%),0) -> 83 | U5: {=_xlfn.IFS(T5>=90,"Low",T5>=75,"Moderate",T5>=60,"Elevated",TRUE,"High")} -> Moderate | V5: =IF(OR(I5="Critical",I5="High"),"Yes","No") -> Yes | W5: 46752 | X5: =_xlfn.XLOOKUP(I5,'Lookup Tables'!$H$4:$H$7,'Lookup Tables'!$I$4:$I$7) -> 90 | Y5: Approved | Z5: AI-enabled edge computing platform supporting smart port operations.
A6: V005 | B6: Salesforce | C6: CRM | D6: Customer Experience | E6: NovaPortal | F6: Director, Customer Experience | G6: Enterprise Applications Manager | H6: Chief Customer Officer | I6: High | J6: Confidential | K6: Global | L6: GDPR | M6: 46218 | N6: =M6+X6 -> 46398 | O6: 91 | P6: 90 | Q6: 85 | R6: 89 | S6: 75 | T6: =ROUND((O6*25%)+(P6*25%)+(Q6*20%)+(R6*20%)+(S6*10%),0) -> 88 | U6: {=_xlfn.IFS(T6>=90,"Low",T6>=75,"Moderate",T6>=60,"Elevated",TRUE,"High")} -> Moderate | V6: =IF(OR(I6="Critical",I6="High"),"Yes","No") -> Yes | W6: 46568 | X6: =_xlfn.XLOOKUP(I6,'Lookup Tables'!$H$4:$H$7,'Lookup Tables'!$I$4:$I$7) -> 180 | Y6: Approved | Z6: Critical service provider. Continuous monitoring enabled.
A7: V006 | B7: ServiceNow | C7: IT Service Management | D7: IT Operations | E7: ServiceNow | F7: Director, Enterprise IT Services | G7: Enterprise Applications Manager | H7: CIO | I7: High | J7: Confidential | K7: Global | L7: GDPR | M7: 46218 | N7: =M7+X7 -> 46398 | O7: 92 | P7: 91 | Q7: 86 | R7: 90 | S7: 73 | T7: =ROUND((O7*25%)+(P7*25%)+(Q7*20%)+(R7*20%)+(S7*10%),0) -> 88 | U7: {=_xlfn.IFS(T7>=90,"Low",T7>=75,"Moderate",T7>=60,"Elevated",TRUE,"High")} -> Moderate | V7: =IF(OR(I7="Critical",I7="High"),"Yes","No") -> Yes | W7: 46568 | X7: =_xlfn.XLOOKUP(I7,'Lookup Tables'!$H$4:$H$7,'Lookup Tables'!$I$4:$I$7) -> 180 | Y7: Approved | Z7: Critical service provider. Continuous monitoring enabled.
A8: V007 | B8: GitHub | C8: Software Development | D8: Application Development | E8: GitHub Enterprise | F8: Director, Software Engineering | G8: DevSecOps Platform Manager | H8: CIO | I8: High | J8: Internal | K8: Global | L8: None | M8: 46218 | N8: =M8+X8 -> 46398 | O8: 90 | P8: 88 | Q8: 82 | R8: 88 | S8: 72 | T8: =ROUND((O8*25%)+(P8*25%)+(Q8*20%)+(R8*20%)+(S8*10%),0) -> 86 | U8: {=_xlfn.IFS(T8>=90,"Low",T8>=75,"Moderate",T8>=60,"Elevated",TRUE,"High")} -> Moderate | V8: =IF(OR(I8="Critical",I8="High"),"Yes","No") -> Yes | W8: 46568 | X8: =_xlfn.XLOOKUP(I8,'Lookup Tables'!$H$4:$H$7,'Lookup Tables'!$I$4:$I$7) -> 180 | Y8: Approved | Z8: Critical service provider. Continuous monitoring enabled.
A9: V008 | B9: Cloudflare | C9: Network Security | D9: Internet Services | E9: External Services | F9: Director, Infrastructure Services | G9: Network Services Manager | H9: CIO | I9: High | J9: Internal | K9: Global | L9: GDPR | M9: 46218 | N9: =M9+X9 -> 46398 | O9: 89 | P9: 92 | Q9: 83 | R9: 90 | S9: 71 | T9: =ROUND((O9*25%)+(P9*25%)+(Q9*20%)+(R9*20%)+(S9*10%),0) -> 87 | U9: {=_xlfn.IFS(T9>=90,"Low",T9>=75,"Moderate",T9>=60,"Elevated",TRUE,"High")} -> Moderate | V9: =IF(OR(I9="Critical",I9="High"),"Yes","No") -> Yes | W9: 46568 | X9: =_xlfn.XLOOKUP(I9,'Lookup Tables'!$H$4:$H$7,'Lookup Tables'!$I$4:$I$7) -> 180 | Y9: Approved | Z9: Critical service provider. Continuous monitoring enabled.
A10: V009 | B10: CrowdStrike | C10: Endpoint Security | D10: Cybersecurity | E10: EDR Platform | F10: Director, Cybersecurity Operations | G10: Security Engineering Manager | H10: CISO | I10: High | J10: Confidential | K10: Global | L10: ISO 27001 | M10: 46218 | N10: =M10+X10 -> 46398 | O10: 91 | P10: 95 | Q10: 84 | R10: 93 | S10: 69 | T10: =ROUND((O10*25%)+(P10*25%)+(Q10*20%)+(R10*20%)+(S10*10%),0) -> 89 | U10: {=_xlfn.IFS(T10>=90,"Low",T10>=75,"Moderate",T10>=60,"Elevated",TRUE,"High")} -> Moderate | V10: =IF(OR(I10="Critical",I10="High"),"Yes","No") -> Yes | W10: 46568 | X10: =_xlfn.XLOOKUP(I10,'Lookup Tables'!$H$4:$H$7,'Lookup Tables'!$I$4:$I$7) -> 180 | Y10: Approved | Z10: Critical service provider. Continuous monitoring enabled.
A11: V010 | B11: Palo Alto Networks | C11: Network Security | D11: Cybersecurity | E11: Firewalls | F11: Director, Cybersecurity Operations | G11: Security Engineering Manager | H11: CISO | I11: High | J11: Internal | K11: Global | L11: ISO 27001 | M11: 46218 | N11: =M11+X11 -> 46398 | O11: 91 | P11: 94 | Q11: 85 | R11: 92 | S11: 68 | T11: =ROUND((O11*25%)+(P11*25%)+(Q11*20%)+(R11*20%)+(S11*10%),0) -> 88 | U11: {=_xlfn.IFS(T11>=90,"Low",T11>=75,"Moderate",T11>=60,"Elevated",TRUE,"High")} -> Moderate | V11: =IF(OR(I11="Critical",I11="High"),"Yes","No") -> Yes | W11: 46568 | X11: =_xlfn.XLOOKUP(I11,'Lookup Tables'!$H$4:$H$7,'Lookup Tables'!$I$4:$I$7) -> 180 | Y11: Approved | Z11: Critical service provider. Continuous monitoring enabled.
A12: V011 | B12: Maersk | C12: Maritime Logistics | D12: Ocean Freight | E12: PortFlow | F12: VP, Global Logistics Operations | G12: Logistics Systems Manager | H12: COO | I12: Critical | J12: Confidential | K12: Global | L12: GDPR | M12: 46204 | N12: =M12+X12 -> 46294 | O12: 88 | P12: 89 | Q12: 97 | R12: 87 | S12: 74 | T12: =ROUND((O12*25%)+(P12*25%)+(Q12*20%)+(R12*20%)+(S12*10%),0) -> 88 | U12: {=_xlfn.IFS(T12>=90,"Low",T12>=75,"Moderate",T12>=60,"Elevated",TRUE,"High")} -> Moderate | V12: =IF(OR(I12="Critical",I12="High"),"Yes","No") -> Yes | W12: 46752 | X12: =_xlfn.XLOOKUP(I12,'Lookup Tables'!$H$4:$H$7,'Lookup Tables'!$I$4:$I$7) -> 90 | Y12: Approved | Z12: Strategic maritime logistics partner with global operational dependency.
A13: V012 | B13: DHL Supply Chain | C13: Logistics | D13: Distribution | E13: NovaTrack | F13: VP, Distribution Operations | G13: Logistics Systems Manager | H13: COO | I13: High | J13: Confidential | K13: Global | L13: GDPR | M13: 46218 | N13: =M13+X13 -> 46398 | O13: 86 | P13: 87 | Q13: 92 | R13: 84 | S13: 73 | T13: =ROUND((O13*25%)+(P13*25%)+(Q13*20%)+(R13*20%)+(S13*10%),0) -> 86 | U13: {=_xlfn.IFS(T13>=90,"Low",T13>=75,"Moderate",T13>=60,"Elevated",TRUE,"High")} -> Moderate | V13: =IF(OR(I13="Critical",I13="High"),"Yes","No") -> Yes | W13: 46568 | X13: =_xlfn.XLOOKUP(I13,'Lookup Tables'!$H$4:$H$7,'Lookup Tables'!$I$4:$I$7) -> 180 | Y13: Approved | Z13: Critical service provider. Continuous monitoring enabled.
... A31: V030 | B31: Canva Enterprise | C31: Productivity | D31: Corporate Communications | E31: Design Platform | F31: Director, Corporate Communications | G31: Enterprise Applications Manager | H31: Chief Marketing Officer | I31: Low | J31: Public | K31: Global | L31: None | M31: 46249 | N31: =M31+X31 -> 46979 | O31: 80 | P31: 80 | Q31: 60 | R31: 74 | S31: 70 | T31: =ROUND((O31*25%)+(P31*25%)+(Q31*20%)+(R31*20%)+(S31*10%),0) -> 74 | U31: {=_xlfn.IFS(T31>=90,"Low",T31>=75,"Moderate",T31>=60,"Elevated",TRUE,"High")} -> Elevated | V31: =IF(OR(I31="Critical",I31="High"),"Yes","No") -> No | W31: 46203 | X31: =_xlfn.XLOOKUP(I31,'Lookup Tables'!$H$4:$H$7,'Lookup Tables'!$I$4:$I$7) -> 730 | Y31: Approved | Z31: Low business impact vendor. Annual assessment sufficient.

Sheet Scoring Matrix
B3: Domain | C3: Weight | E3: Score | F3: Interpretation
B4: Governance & Compliance | C4: 0.25 | E4: 95–100 | F4: Industry-leading maturity
B5: Security Posture | C5: 0.25 | E5: 90–94 | F5: Strong, well-controlled
B6: Business Dependency | C6: 0.2 | E6: 80–89 | F6: Mature with minor improvement areas
B7: Continuous Monitoring | C7: 0.2 | E7: 70–79 | F7: Acceptable but requires monitoring
B8: Concentration & Resilience | C8: 0.1 | E8: 60–69 | F8: Weak controls
E9: Below 60 | F9: Significant risk requiring remediation

Sheet Lookup Tables
B3: Composite Score | C3: Risk Tier | E3: Vendor Tier | F3: Monitoring Frequency | H3: Vendor Tier | I3: Half-Life (Days)
B4: 90 | C4: Low | E4: Critical | F4: Continuous | H4: Critical | I4: 90
B5: 75 | C5: Moderate | E5: High | F5: Quarterly | H5: High | I5: 180
B6: 60 | C6: Elevated | E6: Medium | F6: Semi-Annual | H6: Medium | I6: 365
B7: 0 | C7: High | E7: Low | F7: Annual | H7: Low | I7: 730

Sheet Dashboard
A1: NovaTide Logistics TPRM Vendor Risk Dashboard Version 1.0
D2: Tier | E2: Count
D3: Critical | E3: =COUNTIF('Vendor Inventory'!I2:I31,"Critical") -> 5
A4: Metric | B4: Formula | D4: High | E4: =COUNTIF('Vendor Inventory'!I2:I31,"High") -> 11
A5: Total Vendors | B5: =COUNTA('Vendor Inventory'!B2:B31) -> 30 | D5: Medium | E5: =COUNTIF('Vendor Inventory'!I2:I31,"Medium") -> 10
A6: Critical Vendors | B6: =COUNTIF('Vendor Inventory'!I2:I31,"Critical") -> 5 | D6: Low | E6: =COUNTIF('Vendor Inventory'!I2:I31,"Low") -> 4
A7: High Vendors | B7: =COUNTIF('Vendor Inventory'!I2:I31,"High") -> 11
A8: Medium Vendors | B8: =COUNTIF('Vendor Inventory'!I2:I31,"Medium") -> 10 | D8: Category | E8: Count
A9: Low Vendors | B9: =COUNTIF('Vendor Inventory'!I2:I31,"Low") -> 4 | D9: Cloud & Productivity | E9: =COUNTIF('Vendor Inventory'!C2:C31,"Cloud & Productivity") -> 1
A10: Average Composite Score | B10: =ROUND(AVERAGE('Vendor Inventory'!T2:T31),0) -> 85 | D10: ERP | E10: =COUNTIF('Vendor Inventory'!C2:C31,"ERP") -> 1
A11: Vendors Under Continuous Monitoring | B11: =COUNTIF('Vendor Inventory'!V2:V31,"Yes") -> 16 | D11: Data Platform | E11: =COUNTIF('Vendor Inventory'!C2:C31,"Data Platform") -> 1
A12: Average Assessment Half-Life | B12: =ROUND(AVERAGE('Vendor Inventory'!X2:X31),0) -> 300 | D12: AI Platform | E12: =COUNTIF('Vendor Inventory'!C2:C31,"AI Platform") -> 1
D13: Cybersecurity | E13: 5
D14: Logistics | E14: 5
D15: Others | E15: 10
D18: Vendor | E18: Composite Score
D19: Canva Enterprise | E19: ='Vendor Inventory'!T31 -> 74
D20: Miro | E20: ='Vendor Inventory'!T30 -> 76
D21: Adobe | E21: ='Vendor Inventory'!T24 -> 77
D22: Zoom | E22: ='Vendor Inventory'!T29 -> 78
D23: C.H. Robinson | E23: ='Vendor Inventory'!T16 -> 82
D24: NaviEdge Solutions | E24: ='Vendor Inventory'!T5 -> 83
D25: Elastic | E25: ='Vendor Inventory'!T19 -> 83
D26: Verizon Business | E26: ='Vendor Inventory'!T22 -> 83
D27: Atlassian | E27: ='Vendor Inventory'!T25 -> 83
D28: Kuehne+Nagel | E28: ='Vendor Inventory'!T15 -> 84
D29: MongoDB Atlas | E29: ='Vendor Inventory'!T20 -> 84
D30: DocuSign | E30: ='Vendor Inventory'!T23 -> 84
D31: FedEx Logistics | E31: ='Vendor Inventory'!T14 -> 85
D32: Databricks | E32: ='Vendor Inventory'!T18 -> 85
D33: GitHub | E33: ='Vendor Inventory'!T8 -> 86
D34: DHL Supply Chain | E34: ='Vendor Inventory'!T13 -> 86
D35: Fortinet | E35: ='Vendor Inventory'!T28 -> 86
D36: Cloudflare | E36: ='Vendor Inventory'!T9 -> 87
D37: Azure OpenAI Service | E37: ='Vendor Inventory'!T17 -> 87
D38: Cisco | E38: ='Vendor Inventory'!T21 -> 87
D39: Workday | E39: ='Vendor Inventory'!T26 -> 87
D40: Proofpoint | E40: ='Vendor Inventory'!T27 -> 87
D41: Salesforce | E41: ='Vendor Inventory'!T6 -> 88
D42: ServiceNow | E42: ='Vendor Inventory'!T7 -> 88
...
